<?xml version="1.0"?>
<!-- created with Phobos 1.0.1 "Capricious Choutengan" -->
  <robot name="bot">

    <link name="Untitled">
      <inertial>
        <origin xyz="0 0 0" rpy="0 0 0"/>
        <mass value="0.001"/>
        <inertia ixx="0.001" ixy="0" ixz="0" iyy="0.001" iyz="0" izz="0.001"/>
      </inertial>
    </link>

    <link name="Untitled.001">
      <inertial>
        <origin xyz="0 0 0" rpy="0 0 0"/>
        <mass value="0.001"/>
        <inertia ixx="0.001" ixy="0" ixz="0" iyy="0.001" iyz="0" izz="0.001"/>
      </inertial>
    </link>

    <link name="Untitled.002">
      <inertial>
        <origin xyz="0 0 0" rpy="0 0 0"/>
        <mass value="0.001"/>
        <inertia ixx="0.001" ixy="0" ixz="0" iyy="0.001" iyz="0" izz="0.001"/>
      </inertial>
    </link>

    <link name="Untitled.003">
      <inertial>
        <origin xyz="0 0 0" rpy="0 0 0"/>
        <mass value="0.001"/>
        <inertia ixx="0.001" ixy="0" ixz="0" iyy="0.001" iyz="0" izz="0.001"/>
      </inertial>
    </link>

    <link name="Untitled.004">
      <inertial>
        <origin xyz="0 0 0" rpy="0 0 0"/>
        <mass value="8.0"/>
        <inertia ixx="0.00043" ixy="0" ixz="0" iyy="0.00145" iyz="0" izz="0.06667"/>
      </inertial>
      <visual name="base link.000">
        <origin xyz="0 0 0" rpy="0 0 0"/>
        <geometry>
          <box size="0.5 0.2 0.1"/>
        </geometry>
        <material name="Material.005"/>
      </visual>
      <collision name="base link.000">
        <origin xyz="0 0 0" rpy="0 0 0"/>
        <geometry>
          <box size="0.5 0.2 0.1"/>
        </geometry>
      </collision>
    </link>

    <link name="Untitled.005">
      <inertial>
        <origin xyz="0 0 0" rpy="0 0 0"/>
        <mass value="0.25"/>
        <inertia ixx="7e-05" ixy="0" ixz="0" iyy="0.00013" iyz="0" izz="0.00056"/>
      </inertial>
      <visual name="bl Link.000">
        <origin xyz="-0.0022 0 0" rpy="-3.14159 0 0"/>
        <geometry>
          <mesh filename="Cylinder.004.stl" scale="0.77778 0.77778 1.0"/>
        </geometry>
        <material name="Material.004"/>
      </visual>
      <collision name="bl Link.000">
        <origin xyz="-0.0022 0 0" rpy="-3.14159 0 0"/>
        <geometry>
          <cylinder radius="0.07" length="0.05"/>
        </geometry>
      </collision>
    </link>

    <link name="Untitled.006">
      <inertial>
        <origin xyz="0 0 0" rpy="0 0 0"/>
        <mass value="0.25"/>
        <inertia ixx="7e-05" ixy="0" ixz="0" iyy="0.00013" iyz="0" izz="0.00056"/>
      </inertial>
      <visual name="bl Link.002.000">
        <origin xyz="-0.0022 0 0" rpy="-3.14159 0 0"/>
        <geometry>
          <cylinder radius="0.07" length="0.05"/>
        </geometry>
        <material name="Material.001"/>
      </visual>
      <collision name="bl Link.002.000">
        <origin xyz="-0.0022 0 0" rpy="-3.14159 0 0"/>
        <geometry>
          <cylinder radius="0.07" length="0.05"/>
        </geometry>
      </collision>
    </link>

    <link name="Untitled.007">
      <inertial>
        <origin xyz="0 0 0" rpy="0 0 0"/>
        <mass value="0.25"/>
        <inertia ixx="7e-05" ixy="0" ixz="0" iyy="0.00013" iyz="0" izz="0.00056"/>
      </inertial>
      <visual name="bl Link.003.000">
        <origin xyz="-0.0022 0 0" rpy="0 0 0"/>
        <geometry>
          <cylinder radius="0.07" length="0.05"/>
        </geometry>
        <material name="Material.002"/>
      </visual>
      <collision name="bl Link.003.000">
        <origin xyz="-0.0022 0 0" rpy="0 0 0"/>
        <geometry>
          <cylinder radius="0.07" length="0.05"/>
        </geometry>
      </collision>
    </link>

    <link name="Untitled.008">
      <inertial>
        <origin xyz="0 0 0" rpy="0 0 0"/>
        <mass value="0.25"/>
        <inertia ixx="7e-05" ixy="0" ixz="0" iyy="0.00013" iyz="0" izz="0.00056"/>
      </inertial>
      <visual name="bl Link.001.000">
        <origin xyz="-0.0022 0 0" rpy="0 0 0"/>
        <geometry>
          <cylinder radius="0.07" length="0.05"/>
        </geometry>
        <material name="Material.003"/>
      </visual>
      <collision name="bl Link.001.000">
        <origin xyz="-0.0022 0 0" rpy="0 0 0"/>
        <geometry>
          <cylinder radius="0.07" length="0.05"/>
        </geometry>
      </collision>
    </link>

    <link name="Untitled.009">
      <inertial>
        <origin xyz="0 0 0" rpy="0 0 0"/>
        <mass value="8.0"/>
        <inertia ixx="0.00043" ixy="0" ixz="0" iyy="0.00145" iyz="0" izz="0.06667"/>
      </inertial>
      <visual name="base link.001">
        <origin xyz="0 0 0" rpy="0 0 0"/>
        <geometry>
          <box size="0.5 0.2 0.1"/>
        </geometry>
        <material name="Material.005"/>
      </visual>
      <collision name="base link.000">
        <origin xyz="0 0 0" rpy="0 0 0"/>
        <geometry>
          <box size="0.5 0.2 0.1"/>
        </geometry>
      </collision>
    </link>

    <link name="Untitled.010">
      <inertial>
        <origin xyz="0 0 0" rpy="0 0 0"/>
        <mass value="0.001"/>
        <inertia ixx="0.001" ixy="0" ixz="0" iyy="0.001" iyz="0" izz="0.001"/>
      </inertial>
    </link>

    <link name="Untitled.011">
      <inertial>
        <origin xyz="0 0 0" rpy="0 0 0"/>
        <mass value="0.25"/>
        <inertia ixx="7e-05" ixy="0" ixz="0" iyy="0.00013" iyz="0" izz="0.00056"/>
      </inertial>
      <visual name="bl Link.003.001">
        <origin xyz="-0.0022 0 0" rpy="0 0 0"/>
        <geometry>
          <cylinder radius="0.07" length="0.05"/>
        </geometry>
        <material name="Material.002"/>
      </visual>
      <collision name="bl Link.003.000">
        <origin xyz="-0.0022 0 0" rpy="0 0 0"/>
        <geometry>
          <cylinder radius="0.07" length="0.05"/>
        </geometry>
      </collision>
    </link>

    <link name="Untitled.012">
      <inertial>
        <origin xyz="0 0 0" rpy="0 0 0"/>
        <mass value="0.001"/>
        <inertia ixx="0.001" ixy="0" ixz="0" iyy="0.001" iyz="0" izz="0.001"/>
      </inertial>
    </link>

    <link name="Untitled.013">
      <inertial>
        <origin xyz="0 0 0" rpy="0 0 0"/>
        <mass value="0.001"/>
        <inertia ixx="0.001" ixy="0" ixz="0" iyy="0.001" iyz="0" izz="0.001"/>
      </inertial>
      <visual name="Pulley T-Mxl-Xl-Htd-Gt2 N-Tooth 20141225-11880-1Y2Kfq6-0">
        <origin xyz="0 0 -0.05" rpy="0 0 0"/>
        <geometry>
          <mesh filename="Pulley T-Mxl-Xl-Htd-Gt2 N-Tooth 20141225-11880-1Y2Kfq6-0.stl" scale="0.00021 0.00037 0.005"/>
        </geometry>
        <material name="Material.039"/>
      </visual>
    </link>

    <link name="Untitled.014">
      <inertial>
        <origin xyz="0 0 0" rpy="0 0 0"/>
        <mass value="0.001"/>
        <inertia ixx="0.001" ixy="0" ixz="0" iyy="0.001" iyz="0" izz="0.001"/>
      </inertial>
    </link>

    <link name="Untitled.015">
      <inertial>
        <origin xyz="0 0 0" rpy="0 0 0"/>
        <mass value="0.25"/>
        <inertia ixx="7e-05" ixy="0" ixz="0" iyy="0.00013" iyz="0" izz="0.00056"/>
      </inertial>
      <visual name="bl Link.001">
        <origin xyz="-0.0022 0 0" rpy="-3.14159 0 0"/>
        <geometry>
          <cylinder radius="0.07" length="0.05"/>
        </geometry>
        <material name="Material.004"/>
      </visual>
      <collision name="bl Link.000">
        <origin xyz="-0.0022 0 0" rpy="-3.14159 0 0"/>
        <geometry>
          <cylinder radius="0.07" length="0.05"/>
        </geometry>
      </collision>
    </link>

    <link name="Untitled.016">
      <inertial>
        <origin xyz="0 0 0" rpy="0 0 0"/>
        <mass value="0.001"/>
        <inertia ixx="0.001" ixy="0" ixz="0" iyy="0.001" iyz="0" izz="0.001"/>
      </inertial>
    </link>

    <link name="Untitled.017">
      <inertial>
        <origin xyz="0 0 0" rpy="0 0 0"/>
        <mass value="0.25"/>
        <inertia ixx="7e-05" ixy="0" ixz="0" iyy="0.00013" iyz="0" izz="0.00056"/>
      </inertial>
      <visual name="bl Link.001.001">
        <origin xyz="-0.0022 0 0" rpy="0 0 0"/>
        <geometry>
          <cylinder radius="0.07" length="0.05"/>
        </geometry>
        <material name="Material.003"/>
      </visual>
      <collision name="bl Link.001.000">
        <origin xyz="-0.0022 0 0" rpy="0 0 0"/>
        <geometry>
          <cylinder radius="0.07" length="0.05"/>
        </geometry>
      </collision>
    </link>

    <link name="Untitled.018">
      <inertial>
        <origin xyz="0 0 0" rpy="0 0 0"/>
        <mass value="0.02"/>
        <inertia ixx="2e-05" ixy="0" ixz="0" iyy="2e-05" iyz="0" izz="2e-05"/>
      </inertial>
      <visual name="base link.002">
        <origin xyz="0 0 0" rpy="0 0 0"/>
        <geometry>
          <mesh filename="base link.stl" scale="0.74892 0.75 0.33333"/>
        </geometry>
        <material name="Material.035"/>
      </visual>
      <collision name="base link.002.000">
        <origin xyz="0 0 0" rpy="0 0 0"/>
        <geometry>
          <mesh filename="base link.001.stl" scale="1.5043 1.5 1.0"/>
        </geometry>
      </collision>
    </link>

    <link name="Untitled.019">
      <inertial>
        <origin xyz="0 0 0" rpy="0 0 0"/>
        <mass value="0.01"/>
        <inertia ixx="2e-05" ixy="0" ixz="0" iyy="2e-05" iyz="0" izz="2e-05"/>
      </inertial>
      <visual name="inner Link.003">
        <origin xyz="0 0 0" rpy="0 0 0"/>
        <geometry>
          <mesh filename="inner Link.006.stl" scale="0.59176 0.57692 0.33333"/>
        </geometry>
        <material name="Material.036"/>
      </visual>
      <collision name="inner Link.003.000">
        <origin xyz="0 0 0" rpy="0 0 0"/>
        <geometry>
          <mesh filename="inner Link.007.stl" scale="1.0 1.0 1.0"/>
        </geometry>
      </collision>
    </link>

    <link name="Untitled.020">
      <inertial>
        <origin xyz="0 0 0" rpy="0 0 0"/>
        <mass value="0.001"/>
        <inertia ixx="2e-05" ixy="0" ixz="0" iyy="2e-05" iyz="0" izz="2e-05"/>
      </inertial>
      <visual name="Half Sphere 2">
        <origin xyz="0 0 0" rpy="-1.5708 0 0"/>
        <geometry>
          <mesh filename="Half Sphere 2.002.stl" scale="0.00489 0.00488 0.00488"/>
        </geometry>
        <material name="Material.037"/>
      </visual>
      <collision name="Half Sphere 2.000">
        <origin xyz="-0.001 0 -0.00176" rpy="-1.5708 0 0"/>
        <geometry>
          <mesh filename="Half Sphere 2.003.stl" scale="1.0 1.0 1.0"/>
        </geometry>
      </collision>
    </link>

    <link name="Untitled.021">
      <inertial>
        <origin xyz="0 0 0.01" rpy="0 0 0"/>
        <mass value="0.01"/>
        <inertia ixx="2e-05" ixy="0" ixz="0" iyy="2e-05" iyz="0" izz="2e-05"/>
      </inertial>
      <visual name="Cube.003">
        <origin xyz="0 0 0.01" rpy="0 0 0"/>
        <geometry>
          <box size="0.15 0.03 0.01"/>
        </geometry>
        <material name="Material.009"/>
      </visual>
      <collision name="Cube.003">
        <origin xyz="0 0 0.01" rpy="0 0 0"/>
        <geometry>
          <box size="0.15 0.03 0.01"/>
        </geometry>
      </collision>
    </link>

    <link name="Untitled.022">
      <inertial>
        <origin xyz="0 0 0" rpy="0 0 0"/>
        <mass value="0.05"/>
        <inertia ixx="2e-05" ixy="0" ixz="0" iyy="2e-05" iyz="0" izz="2e-05"/>
      </inertial>
      <visual name="Cube.002">
        <origin xyz="0 0 0" rpy="0 0 0"/>
        <geometry>
          <box size="0.03 0.03 0.06"/>
        </geometry>
        <material name="Material.010"/>
      </visual>
      <collision name="Cube.002">
        <origin xyz="0 0 0" rpy="0 0 0"/>
        <geometry>
          <box size="0.03 0.03 0.06"/>
        </geometry>
      </collision>
    </link>

    <link name="Untitled.023">
      <inertial>
        <origin xyz="0 0 0" rpy="0 0 0"/>
        <mass value="0.05"/>
        <inertia ixx="2e-05" ixy="0" ixz="0" iyy="2e-05" iyz="0" izz="2e-05"/>
      </inertial>
      <visual name="Cube.001">
        <origin xyz="0 0 0" rpy="0 0 0"/>
        <geometry>
          <box size="0.03 0.03 0.06"/>
        </geometry>
        <material name="Material.010"/>
      </visual>
      <collision name="Cube.001">
        <origin xyz="0 0 0" rpy="0 0 0"/>
        <geometry>
          <box size="0.03 0.03 0.06"/>
        </geometry>
      </collision>
    </link>

    <link name="Untitled.024">
      <inertial>
        <origin xyz="0 0 0" rpy="0 0 0"/>
        <mass value="0.001"/>
        <inertia ixx="0.001" ixy="0" ixz="0" iyy="0.001" iyz="0" izz="0.001"/>
      </inertial>
    </link>

    <link name="Untitled.025">
      <inertial>
        <origin xyz="0 0 0" rpy="0 0 0"/>
        <mass value="0.001"/>
        <inertia ixx="0.001" ixy="0" ixz="0" iyy="0.001" iyz="0" izz="0.001"/>
      </inertial>
    </link>

    <link name="Untitled.026">
      <inertial>
        <origin xyz="0 0 0" rpy="0 0 0"/>
        <mass value="0.5"/>
        <inertia ixx="2e-05" ixy="0" ixz="0" iyy="2e-05" iyz="0" izz="2e-05"/>
      </inertial>
      <visual name="Cube">
        <origin xyz="0 0 0" rpy="-1.5708 0 0"/>
        <geometry>
          <box size="0.2 0.2 0.04"/>
        </geometry>
        <material name="Material.008"/>
      </visual>
      <collision name="Cube">
        <origin xyz="0 0 0" rpy="-1.5708 0 0"/>
        <geometry>
          <box size="0.2 0.2 0.04"/>
        </geometry>
      </collision>
    </link>

    <link name="Untitled.027">
      <inertial>
        <origin xyz="0 0 0" rpy="0 0 0"/>
        <mass value="0.5"/>
        <inertia ixx="0.00286" ixy="0" ixz="0" iyy="0.00286" iyz="0" izz="0.0001"/>
      </inertial>
      <visual name="base link">
        <origin xyz="0 0 0" rpy="0 0 0"/>
        <geometry>
          <mesh filename="base link.006.stl" scale="1.0 1.0 1.0"/>
        </geometry>
        <material name="Material.011"/>
      </visual>
      <collision name="base link.000.001.002">
        <origin xyz="0 0.00061 0" rpy="0 0 0"/>
        <geometry>
          <mesh filename="base link.009.stl" scale="1.0 1.0 1.0"/>
        </geometry>
      </collision>
    </link>

    <link name="Untitled.028">
      <inertial>
        <origin xyz="0 0 0.02952" rpy="0 0 0"/>
        <mass value="0.5"/>
        <inertia ixx="0.00377" ixy="0" ixz="0" iyy="0.00377" iyz="0" izz="4e-05"/>
      </inertial>
      <visual name="inner Link">
        <origin xyz="0 0 0.02952" rpy="0 0 0"/>
        <geometry>
          <mesh filename="inner Link.stl" scale="1.0 1.0 1.0"/>
        </geometry>
        <material name="Material.012"/>
      </visual>
      <collision name="inner Link.000">
        <origin xyz="0 0 0.02952" rpy="0 0 0"/>
        <geometry>
          <mesh filename="inner Link.003.stl" scale="1.0 1.0 1.0"/>
        </geometry>
      </collision>
    </link>

    <link name="Untitled.029">
      <inertial>
        <origin xyz="0 0 0" rpy="0 0 0"/>
        <mass value="0.1"/>
        <inertia ixx="2e-05" ixy="0" ixz="0" iyy="2e-05" iyz="0" izz="2e-05"/>
      </inertial>
      <visual name="Cube.004">
        <origin xyz="0 0 0" rpy="0 0 0"/>
        <geometry>
          <box size="0.06 0.026 0.01"/>
        </geometry>
        <material name="Material.013"/>
      </visual>
      <collision name="Cube.004">
        <origin xyz="0 0 0" rpy="0 0 0"/>
        <geometry>
          <box size="0.06 0.026 0.01"/>
        </geometry>
      </collision>
    </link>

    <link name="Untitled.030">
      <inertial>
        <origin xyz="0 0 0" rpy="0 0 0"/>
        <mass value="0.5"/>
        <inertia ixx="0.00286" ixy="0" ixz="0" iyy="0.00286" iyz="0" izz="0.0001"/>
      </inertial>
      <visual name="base link.003">
        <origin xyz="0 0 0" rpy="0 0 0"/>
        <geometry>
          <mesh filename="base link.007.stl" scale="1.0 1.0 1.0"/>
        </geometry>
        <material name="Material.014"/>
      </visual>
      <collision name="base link.003.000">
        <origin xyz="0 0 0" rpy="0 0 0"/>
        <geometry>
          <mesh filename="base link.010.stl" scale="1.0 1.0 1.0"/>
        </geometry>
      </collision>
    </link>

    <link name="Untitled.031">
      <inertial>
        <origin xyz="0 0 0" rpy="0 0 0"/>
        <mass value="0.5"/>
        <inertia ixx="0.00377" ixy="0" ixz="0" iyy="0.00377" iyz="0" izz="4e-05"/>
      </inertial>
      <visual name="inner Link.001">
        <origin xyz="0 0 0" rpy="0 0 0"/>
        <geometry>
          <mesh filename="inner Link.001.stl" scale="1.0 1.0 1.0"/>
        </geometry>
        <material name="Material.015"/>
      </visual>
      <collision name="inner Link.001.000">
        <origin xyz="0 0 0" rpy="0 0 0"/>
        <geometry>
          <mesh filename="inner Link.004.stl" scale="1.0 1.0 1.0"/>
        </geometry>
      </collision>
    </link>

    <link name="Untitled.032">
      <inertial>
        <origin xyz="0 0 0" rpy="0 0 0"/>
        <mass value="0.1"/>
        <inertia ixx="2e-05" ixy="0" ixz="0" iyy="2e-05" iyz="0" izz="2e-05"/>
      </inertial>
      <visual name="Cube.005">
        <origin xyz="0 0 0" rpy="0 0 0"/>
        <geometry>
          <box size="0.06 0.026 0.01"/>
        </geometry>
        <material name="Material.016"/>
      </visual>
      <collision name="Cube.005">
        <origin xyz="0 0 0" rpy="0 0 0"/>
        <geometry>
          <box size="0.06 0.026 0.01"/>
        </geometry>
      </collision>
    </link>

    <link name="Untitled.033">
      <inertial>
        <origin xyz="0 0 0" rpy="0 0 0"/>
        <mass value="0.5"/>
        <inertia ixx="0.00286" ixy="0" ixz="0" iyy="0.00286" iyz="0" izz="0.0001"/>
      </inertial>
      <visual name="base link.004">
        <origin xyz="0 0 0" rpy="0 0 0"/>
        <geometry>
          <mesh filename="base link.008.stl" scale="1.0 1.0 1.0"/>
        </geometry>
        <material name="Material.017"/>
      </visual>
      <collision name="base link.004.000">
        <origin xyz="0 0 0" rpy="0 0 0"/>
        <geometry>
          <mesh filename="base link.011.stl" scale="1.0 1.0 1.0"/>
        </geometry>
      </collision>
    </link>

    <link name="Untitled.034">
      <inertial>
        <origin xyz="0 0 0" rpy="0 0 0"/>
        <mass value="0.5"/>
        <inertia ixx="0.00377" ixy="0" ixz="0" iyy="0.00377" iyz="0" izz="4e-05"/>
      </inertial>
      <visual name="inner Link.002">
        <origin xyz="0 0 0" rpy="0 0 0"/>
        <geometry>
          <mesh filename="inner Link.002.stl" scale="1.0 1.0 1.0"/>
        </geometry>
        <material name="Material.018"/>
      </visual>
      <collision name="inner Link.002.000">
        <origin xyz="0 0 0" rpy="0 0 0"/>
        <geometry>
          <mesh filename="inner Link.005.stl" scale="1.0 1.0 1.0"/>
        </geometry>
      </collision>
    </link>

    <link name="Untitled.035">
      <inertial>
        <origin xyz="0 0 0" rpy="0 0 0"/>
        <mass value="0.1"/>
        <inertia ixx="2e-05" ixy="0" ixz="0" iyy="2e-05" iyz="0" izz="2e-05"/>
      </inertial>
      <visual name="Cube.006">
        <origin xyz="0 0 0" rpy="0 0 0"/>
        <geometry>
          <box size="0.06 0.026 0.01"/>
        </geometry>
        <material name="Material.019"/>
      </visual>
      <collision name="Cube.006">
        <origin xyz="0 0 0" rpy="0 0 0"/>
        <geometry>
          <box size="0.06 0.026 0.01"/>
        </geometry>
      </collision>
    </link>

    <link name="Untitled.036">
      <inertial>
        <origin xyz="0 0 0" rpy="0 0 0"/>
        <mass value="0.3"/>
        <inertia ixx="2e-05" ixy="0" ixz="0" iyy="2e-05" iyz="0" izz="2e-05"/>
      </inertial>
      <visual name="Cube.007">
        <origin xyz="0 0 0" rpy="0 0 0"/>
        <geometry>
          <box size="0.06 0.15 0.08"/>
        </geometry>
        <material name="Material.020"/>
      </visual>
      <collision name="Cube.007">
        <origin xyz="0 0 0" rpy="0 0 0"/>
        <geometry>
          <box size="0.04 0.15 0.08"/>
        </geometry>
      </collision>
    </link>

    <link name="Untitled.037">
      <inertial>
        <origin xyz="0 0 0.01" rpy="0 0 0"/>
        <mass value="0.05"/>
        <inertia ixx="2e-05" ixy="0" ixz="0" iyy="2e-05" iyz="0" izz="2e-05"/>
      </inertial>
      <visual name="Cube.008">
        <origin xyz="0 0 0.01" rpy="-1.5708 0 0"/>
        <geometry>
          <box size="0.06 0.005 0.1"/>
        </geometry>
        <material name="Material.007"/>
      </visual>
      <collision name="Cube.008">
        <origin xyz="0 0 0.01" rpy="-1.5708 0 0"/>
        <geometry>
          <box size="0.06 0.005 0.1"/>
        </geometry>
      </collision>
    </link>

    <link name="Untitled.038">
      <inertial>
        <origin xyz="0 0 0.01" rpy="0 0 0"/>
        <mass value="0.05"/>
        <inertia ixx="2e-05" ixy="0" ixz="0" iyy="2e-05" iyz="0" izz="2e-05"/>
      </inertial>
      <visual name="Cube.009">
        <origin xyz="0 0 0.01" rpy="-1.5708 0 0"/>
        <geometry>
          <box size="0.06 0.005 0.1"/>
        </geometry>
        <material name="Material.007"/>
      </visual>
      <collision name="Cube.009">
        <origin xyz="0 0 0.01" rpy="-1.5708 0 0"/>
        <geometry>
          <box size="0.06 0.005 0.1"/>
        </geometry>
      </collision>
    </link>

    <link name="Untitled.039">
      <inertial>
        <origin xyz="0 0 0" rpy="0 0 0"/>
        <mass value="0.001"/>
        <inertia ixx="0.001" ixy="0" ixz="0" iyy="0.001" iyz="0" izz="0.001"/>
      </inertial>
      <visual name="L bracket.007">
        <origin xyz="0 0 -0.02" rpy="0 0 0"/>
        <geometry>
          <mesh filename="L bracket.stl" scale="0.00116 0.0016 0.00167"/>
        </geometry>
        <material name="Material.051"/>
      </visual>
    </link>

    <link name="Untitled.040">
      <inertial>
        <origin xyz="0 0 0" rpy="0 0 0"/>
        <mass value="0.001"/>
        <inertia ixx="0.001" ixy="0" ixz="0" iyy="0.001" iyz="0" izz="0.001"/>
      </inertial>
      <visual name="L bracket.004">
        <origin xyz="0 0 0" rpy="0 0 0"/>
        <geometry>
          <mesh filename="L bracket.stl" scale="0.00116 0.0016 0.00167"/>
        </geometry>
        <material name="Material.051"/>
      </visual>
    </link>

    <link name="Untitled.041">
      <inertial>
        <origin xyz="0 0 0" rpy="0 0 0"/>
        <mass value="0.005"/>
        <inertia ixx="2e-05" ixy="0" ixz="0" iyy="2e-05" iyz="0" izz="2e-05"/>
      </inertial>
      <visual name="Cube.012.000">
        <origin xyz="0 0 0" rpy="0 0 0"/>
        <geometry>
          <box size="0.06 0.026 0.01"/>
        </geometry>
        <material name="Material.025"/>
      </visual>
      <collision name="Cube.012.000">
        <origin xyz="0 0 0" rpy="0 0 0"/>
        <geometry>
          <box size="0.06 0.026 0.01"/>
        </geometry>
      </collision>
    </link>

    <link name="Untitled.042">
      <inertial>
        <origin xyz="0 0 0.01" rpy="0 0 0"/>
        <mass value="0.005"/>
        <inertia ixx="2e-05" ixy="0" ixz="0" iyy="2e-05" iyz="0" izz="2e-05"/>
      </inertial>
      <visual name="Cube.013">
        <origin xyz="0 0 0.01" rpy="-1.5708 0 -1.5708"/>
        <geometry>
          <box size="0.02 0.05 0.01"/>
        </geometry>
        <material name="Material.026"/>
      </visual>
      <collision name="Cube.013">
        <origin xyz="0 0 0.01" rpy="-1.5708 0 -1.5708"/>
        <geometry>
          <box size="0.02 0.05 0.01"/>
        </geometry>
      </collision>
    </link>

    <link name="Untitled.043">
      <inertial>
        <origin xyz="0 0 0" rpy="0 0 0"/>
        <mass value="0.001"/>
        <inertia ixx="0.001" ixy="0" ixz="0" iyy="0.001" iyz="0" izz="0.001"/>
      </inertial>
      <visual name="Cylinder.001">
        <origin xyz="0 0 0" rpy="0 0 0"/>
        <geometry>
          <cylinder radius="0.005" length="0.01"/>
        </geometry>
        <material name="Material.027"/>
      </visual>
    </link>

    <link name="Untitled.044">
      <inertial>
        <origin xyz="0 0 0" rpy="0 0 0"/>
        <mass value="0.001"/>
        <inertia ixx="0.001" ixy="0" ixz="0" iyy="0.001" iyz="0" izz="0.001"/>
      </inertial>
      <visual name="Cylinder">
        <origin xyz="0 0 0" rpy="0 0 0"/>
        <geometry>
          <cylinder radius="0.005" length="0.01"/>
        </geometry>
        <material name="Material.027"/>
      </visual>
    </link>

    <link name="Untitled.045">
      <inertial>
        <origin xyz="0 0 0" rpy="0 0 0"/>
        <mass value="0.001"/>
        <inertia ixx="0.001" ixy="0" ixz="0" iyy="0.001" iyz="0" izz="0.001"/>
      </inertial>
      <visual name="L bracket.008">
        <origin xyz="0 0 0" rpy="0 0 0"/>
        <geometry>
          <mesh filename="L bracket.stl" scale="0.00116 0.0016 0.00167"/>
        </geometry>
        <material name="Material.051"/>
      </visual>
    </link>

    <link name="Untitled.046">
      <inertial>
        <origin xyz="0 0 0" rpy="0 0 0"/>
        <mass value="0.001"/>
        <inertia ixx="0.001" ixy="0" ixz="0" iyy="0.001" iyz="0" izz="0.001"/>
      </inertial>
      <visual name="L bracket.011">
        <origin xyz="0 0 0" rpy="0 0 0"/>
        <geometry>
          <mesh filename="L bracket.stl" scale="0.00116 0.0016 0.00167"/>
        </geometry>
        <material name="Material.051"/>
      </visual>
    </link>

    <link name="Untitled.047">
      <inertial>
        <origin xyz="0 0 0" rpy="0 0 0"/>
        <mass value="0.01"/>
        <inertia ixx="2e-05" ixy="0" ixz="0" iyy="2e-05" iyz="0" izz="2e-05"/>
      </inertial>
      <visual name="Cube.012">
        <origin xyz="0 0 0" rpy="0 0 0"/>
        <geometry>
          <box size="0.04 0.05 0.01"/>
        </geometry>
        <material name="Material.032"/>
      </visual>
      <collision name="Cube.012">
        <origin xyz="0 0 0" rpy="0 0 0"/>
        <geometry>
          <box size="0.04 0.05 0.01"/>
        </geometry>
      </collision>
    </link>

    <link name="Untitled.048">
      <inertial>
        <origin xyz="0 0 0" rpy="0 0 0"/>
        <mass value="0.001"/>
        <inertia ixx="0.001" ixy="0" ixz="0" iyy="0.001" iyz="0" izz="0.001"/>
      </inertial>
      <visual name="Cube.014">
        <origin xyz="0 0 0" rpy="0 0 0"/>
        <geometry>
          <box size="0.1 0.07 0.03"/>
        </geometry>
        <material name="Material.041"/>
      </visual>
    </link>

    <link name="Untitled.049">
      <inertial>
        <origin xyz="0 0 0" rpy="0 0 0"/>
        <mass value="0.001"/>
        <inertia ixx="0.001" ixy="0" ixz="0" iyy="0.001" iyz="0" izz="0.001"/>
      </inertial>
      <visual name="Cube.015">
        <origin xyz="0 0 0" rpy="0 0 0"/>
        <geometry>
          <box size="0.05 0.05 0.08"/>
        </geometry>
        <material name="Material.042"/>
      </visual>
    </link>

    <link name="Untitled.050">
      <inertial>
        <origin xyz="0 0 0" rpy="0 0 0"/>
        <mass value="0.001"/>
        <inertia ixx="0.001" ixy="0" ixz="0" iyy="0.001" iyz="0" izz="0.001"/>
      </inertial>
      <visual name="L bracket.009">
        <origin xyz="0.01 0 0" rpy="0 0 0"/>
        <geometry>
          <mesh filename="L bracket.stl" scale="0.00116 0.0016 0.00167"/>
        </geometry>
        <material name="Material.051"/>
      </visual>
    </link>

    <link name="Untitled.051">
      <inertial>
        <origin xyz="0 0 0" rpy="0 0 0"/>
        <mass value="0.001"/>
        <inertia ixx="0.001" ixy="0" ixz="0" iyy="0.001" iyz="0" izz="0.001"/>
      </inertial>
      <visual name="L bracket.010">
        <origin xyz="0 0 0" rpy="0 0 0"/>
        <geometry>
          <mesh filename="L bracket.stl" scale="0.00116 0.0016 0.00167"/>
        </geometry>
        <material name="Material.051"/>
      </visual>
    </link>

    <link name="Untitled.052">
      <inertial>
        <origin xyz="0 0 0" rpy="0 0 0"/>
        <mass value="2.0"/>
        <inertia ixx="1.00174" ixy="0" ixz="0" iyy="0.00057" iyz="0" izz="0.92057"/>
      </inertial>
      <visual name="horizantal rod">
        <origin xyz="0 0 0" rpy="0 0 0"/>
        <geometry>
          <mesh filename="horizantal rod.stl" scale="1.02128 1.00001 1.0"/>
        </geometry>
        <material name="Material.030"/>
      </visual>
      <collision name="horizantal rod.000">
        <origin xyz="0 0 0" rpy="0 0 0"/>
        <geometry>
          <mesh filename="horizantal rod.001.stl" scale="1.0 1.0 1.0"/>
        </geometry>
      </collision>
    </link>

    <link name="Untitled.053">
      <inertial>
        <origin xyz="0 0 0" rpy="0 0 0"/>
        <mass value="0.001"/>
        <inertia ixx="0.001" ixy="0" ixz="0" iyy="0.001" iyz="0" izz="0.001"/>
      </inertial>
      <visual name="NEMA 17">
        <origin xyz="0 0 0" rpy="0 0 0"/>
        <geometry>
          <mesh filename="NEMA 17.stl" scale="0.00142 0.00142 0.00221"/>
        </geometry>
        <material name="Material.038"/>
      </visual>
    </link>

    <link name="Untitled.054">
      <inertial>
        <origin xyz="0 0 0" rpy="0 0 0"/>
        <mass value="0.25"/>
        <inertia ixx="7e-05" ixy="0" ixz="0" iyy="0.00013" iyz="0" izz="0.00056"/>
      </inertial>
      <visual name="bl Link.002.001">
        <origin xyz="-0.0022 0 0" rpy="-3.14159 0 0"/>
        <geometry>
          <cylinder radius="0.07" length="0.05"/>
        </geometry>
        <material name="Material.001"/>
      </visual>
      <collision name="bl Link.002.000">
        <origin xyz="-0.0022 0 0" rpy="-3.14159 0 0"/>
        <geometry>
          <cylinder radius="0.07" length="0.05"/>
        </geometry>
      </collision>
    </link>

    <link name="Untitled.055">
      <inertial>
        <origin xyz="0 0 0" rpy="0 0 0"/>
        <mass value="0.001"/>
        <inertia ixx="0.001" ixy="0" ixz="0" iyy="0.001" iyz="0" izz="0.001"/>
      </inertial>
      <visual name="Cylinder.004">
        <origin xyz="0 0 0" rpy="0 0 0"/>
        <geometry>
          <cylinder radius="0.005" length="0.08"/>
        </geometry>
        <material name="Material.040"/>
      </visual>
    </link>

    <link name="Untitled.056">
      <inertial>
        <origin xyz="0 0 0" rpy="0 0 0"/>
        <mass value="0.001"/>
        <inertia ixx="0.001" ixy="0" ixz="0" iyy="0.001" iyz="0" izz="0.001"/>
      </inertial>
      <visual name="Cylinder.005">
        <origin xyz="0 0 0" rpy="0 0 0"/>
        <geometry>
          <cylinder radius="0.005" length="0.11"/>
        </geometry>
        <material name="Material.040"/>
      </visual>
    </link>

    <link name="Untitled.057">
      <inertial>
        <origin xyz="0 0 0" rpy="0 0 0"/>
        <mass value="0.001"/>
        <inertia ixx="0.001" ixy="0" ixz="0" iyy="0.001" iyz="0" izz="0.001"/>
      </inertial>
      <visual name="Cylinder.006">
        <origin xyz="0 0 0" rpy="0 0 0"/>
        <geometry>
          <cylinder radius="0.005" length="0.05"/>
        </geometry>
        <material name="Material.040"/>
      </visual>
    </link>

    <link name="Untitled.058">
      <inertial>
        <origin xyz="0 0 0" rpy="0 0 0"/>
        <mass value="0.001"/>
        <inertia ixx="0.001" ixy="0" ixz="0" iyy="0.001" iyz="0" izz="0.001"/>
      </inertial>
      <visual name="Original.001">
        <origin xyz="0 0 0.02231" rpy="0 0 0"/>
        <geometry>
          <mesh filename="Original.stl" scale="0.1462 0.01681 0.00592"/>
        </geometry>
        <material name="Material.006"/>
      </visual>
    </link>

    <link name="Untitled.059">
      <inertial>
        <origin xyz="0 0 0" rpy="0 0 0"/>
        <mass value="0.001"/>
        <inertia ixx="0.001" ixy="0" ixz="0" iyy="0.001" iyz="0" izz="0.001"/>
      </inertial>
      <visual name="Cylinder.012">
        <origin xyz="0 0 0" rpy="0 0 0"/>
        <geometry>
          <cylinder radius="0.005" length="0.08"/>
        </geometry>
        <material name="Material.040"/>
      </visual>
    </link>

    <link name="Untitled.060">
      <inertial>
        <origin xyz="0 0 0" rpy="0 0 0"/>
        <mass value="0.001"/>
        <inertia ixx="0.001" ixy="0" ixz="0" iyy="0.001" iyz="0" izz="0.001"/>
      </inertial>
      <visual name="Cylinder.010">
        <origin xyz="0 0 0" rpy="0 0 0"/>
        <geometry>
          <cylinder radius="0.005" length="0.11"/>
        </geometry>
        <material name="Material.040"/>
      </visual>
    </link>

    <link name="Untitled.061">
      <inertial>
        <origin xyz="0 0 0" rpy="0 0 0"/>
        <mass value="0.001"/>
        <inertia ixx="0.001" ixy="0" ixz="0" iyy="0.001" iyz="0" izz="0.001"/>
      </inertial>
      <visual name="Cylinder.009">
        <origin xyz="0 0 0" rpy="0 0 0"/>
        <geometry>
          <cylinder radius="0.005" length="0.08"/>
        </geometry>
        <material name="Material.040"/>
      </visual>
      <visual name="Pulley T-Mxl-Xl-Htd-Gt2 N-Tooth 20141225-11880-1Y2Kfq6-0.001">
        <origin xyz="0 0 0.0194" rpy="0 -3.14159 0"/>
        <geometry>
          <mesh filename="Pulley T-Mxl-Xl-Htd-Gt2 N-Tooth 20141225-11880-1Y2Kfq6-0.stl" scale="0.00021 0.00037 0.005"/>
        </geometry>
        <material name="Material.039"/>
      </visual>
    </link>

    <link name="Untitled.062">
      <inertial>
        <origin xyz="0 0 0" rpy="0 0 0"/>
        <mass value="0.001"/>
        <inertia ixx="0.001" ixy="0" ixz="0" iyy="0.001" iyz="0" izz="0.001"/>
      </inertial>
    </link>

    <link name="Untitled.063">
      <inertial>
        <origin xyz="0 0 0" rpy="0 0 0"/>
        <mass value="0.001"/>
        <inertia ixx="0.001" ixy="0" ixz="0" iyy="0.001" iyz="0" izz="0.001"/>
      </inertial>
      <visual name="Cylinder.008">
        <origin xyz="0 0 0" rpy="0 0 0"/>
        <geometry>
          <cylinder radius="0.005" length="0.08"/>
        </geometry>
        <material name="Material.040"/>
      </visual>
    </link>

    <link name="Untitled.064">
      <inertial>
        <origin xyz="0 0 0" rpy="0 0 0"/>
        <mass value="0.001"/>
        <inertia ixx="0.001" ixy="0" ixz="0" iyy="0.001" iyz="0" izz="0.001"/>
      </inertial>
      <visual name="Cylinder.007">
        <origin xyz="0 0 0" rpy="0 0 0"/>
        <geometry>
          <cylinder radius="0.005" length="0.11"/>
        </geometry>
        <material name="Material.040"/>
      </visual>
    </link>

    <link name="Untitled.065">
      <inertial>
        <origin xyz="0 0 0" rpy="0 0 0"/>
        <mass value="0.001"/>
        <inertia ixx="0.001" ixy="0" ixz="0" iyy="0.001" iyz="0" izz="0.001"/>
      </inertial>
      <visual name="Cylinder.011">
        <origin xyz="0 0 0" rpy="0 0 0"/>
        <geometry>
          <cylinder radius="0.005" length="0.08"/>
        </geometry>
        <material name="Material.040"/>
      </visual>
    </link>

    <link name="Untitled.073">
      <inertial>
        <origin xyz="0 0 0" rpy="0 0 0"/>
        <mass value="0.001"/>
        <inertia ixx="0.001" ixy="0" ixz="0" iyy="0.001" iyz="0" izz="0.001"/>
      </inertial>
      <visual name="L bracket.005">
        <origin xyz="0 0 0" rpy="0 0 0"/>
        <geometry>
          <mesh filename="L bracket.stl" scale="0.00116 0.0016 0.00167"/>
        </geometry>
        <material name="Material.051"/>
      </visual>
    </link>

    <link name="Untitled.074">
      <inertial>
        <origin xyz="0 0 0" rpy="0 0 0"/>
        <mass value="0.001"/>
        <inertia ixx="0.001" ixy="0" ixz="0" iyy="0.001" iyz="0" izz="0.001"/>
      </inertial>
      <visual name="L bracket.006">
        <origin xyz="0 0 0" rpy="0 0 0"/>
        <geometry>
          <mesh filename="L bracket.stl" scale="0.00116 0.0016 0.00167"/>
        </geometry>
        <material name="Material.051"/>
      </visual>
    </link>

    <link name="Untitled.075">
      <inertial>
        <origin xyz="0 0 0" rpy="0 0 0"/>
        <mass value="0.001"/>
        <inertia ixx="0.001" ixy="0" ixz="0" iyy="0.001" iyz="0" izz="0.001"/>
      </inertial>
      <visual name="L bracket.001">
        <origin xyz="0 0 0" rpy="0 0 0"/>
        <geometry>
          <mesh filename="L bracket.stl" scale="0.00116 0.0016 0.00167"/>
        </geometry>
        <material name="Material.051"/>
      </visual>
    </link>

    <link name="Untitled.076">
      <inertial>
        <origin xyz="0 0 0" rpy="0 0 0"/>
        <mass value="0.001"/>
        <inertia ixx="0.001" ixy="0" ixz="0" iyy="0.001" iyz="0" izz="0.001"/>
      </inertial>
      <visual name="L bracket.002">
        <origin xyz="0 0 0" rpy="0 0 0"/>
        <geometry>
          <mesh filename="L bracket.stl" scale="0.00116 0.0016 0.00167"/>
        </geometry>
        <material name="Material.051"/>
      </visual>
    </link>

    <link name="Untitled.077">
      <inertial>
        <origin xyz="0 0 0" rpy="0 0 0"/>
        <mass value="0.001"/>
        <inertia ixx="0.001" ixy="0" ixz="0" iyy="0.001" iyz="0" izz="0.001"/>
      </inertial>
      <visual name="L bracket.003">
        <origin xyz="0 0 -0.01" rpy="0 0 0"/>
        <geometry>
          <mesh filename="L bracket.stl" scale="0.00116 0.0016 0.00167"/>
        </geometry>
        <material name="Material.051"/>
      </visual>
    </link>

    <link name="Untitled.078">
      <inertial>
        <origin xyz="0 0 0" rpy="0 0 0"/>
        <mass value="0.001"/>
        <inertia ixx="0.001" ixy="0" ixz="0" iyy="0.001" iyz="0" izz="0.001"/>
      </inertial>
      <visual name="L bracket">
        <origin xyz="0.005 0 0" rpy="0 0 0"/>
        <geometry>
          <mesh filename="L bracket.stl" scale="0.00116 0.0016 0.00167"/>
        </geometry>
        <material name="Material.051"/>
      </visual>
    </link>

    <link name="Untitled.079">
      <inertial>
        <origin xyz="0 0 0" rpy="0 0 0"/>
        <mass value="0.001"/>
        <inertia ixx="0.001" ixy="0" ixz="0" iyy="0.001" iyz="0" izz="0.001"/>
      </inertial>
      <visual name="Original">
        <origin xyz="0 0 0" rpy="0 0 0"/>
        <geometry>
          <mesh filename="Original.stl" scale="0.1462 0.01681 0.00592"/>
        </geometry>
        <material name="Material.006"/>
      </visual>
    </link>

    <link name="Untitled.080">
      <inertial>
        <origin xyz="0 0 0" rpy="0 0 0"/>
        <mass value="0.001"/>
        <inertia ixx="0.001" ixy="0" ixz="0" iyy="0.001" iyz="0" izz="0.001"/>
      </inertial>
      <visual name="Cube.010">
        <origin xyz="0 0 0" rpy="0 0 0"/>
        <geometry>
          <box size="0.01 0.026 0.05"/>
        </geometry>
        <material name="Material.033"/>
      </visual>
    </link>

    <link name="Untitled.081">
      <inertial>
        <origin xyz="0 0 0" rpy="0 0 0"/>
        <mass value="0.001"/>
        <inertia ixx="0.001" ixy="0" ixz="0" iyy="0.001" iyz="0" izz="0.001"/>
      </inertial>
      <visual name="Cube.011">
        <origin xyz="0 0 0" rpy="0 0 0"/>
        <geometry>
          <box size="0.01 0.026 0.05"/>
        </geometry>
        <material name="Material.033"/>
      </visual>
    </link>

    <link name="Untitled.082">
      <inertial>
        <origin xyz="0 0 0" rpy="0 0 0"/>
        <mass value="0.001"/>
        <inertia ixx="0.001" ixy="0" ixz="0" iyy="0.001" iyz="0" izz="0.001"/>
      </inertial>
      <visual name="Cylinder.002">
        <origin xyz="0 0 0" rpy="0 0 0"/>
        <geometry>
          <cylinder radius="0.015" length="0.06"/>
        </geometry>
        <material name="Material.034"/>
      </visual>
    </link>

    <link name="Untitled.083">
      <inertial>
        <origin xyz="0 0 0" rpy="0 0 0"/>
        <mass value="0.001"/>
        <inertia ixx="0.001" ixy="0" ixz="0" iyy="0.001" iyz="0" izz="0.001"/>
      </inertial>
      <visual name="Cylinder.003">
        <origin xyz="0 0 0" rpy="0 0 0"/>
        <geometry>
          <cylinder radius="0.015" length="0.06"/>
        </geometry>
        <material name="Material.034"/>
      </visual>
    </link>

    <link name="Untitled.084">
      <inertial>
        <origin xyz="0 0 0" rpy="0 0 0"/>
        <mass value="0.001"/>
        <inertia ixx="0.001" ixy="0" ixz="0" iyy="0.001" iyz="0" izz="0.001"/>
      </inertial>
      <visual name="Cylinder.013">
        <origin xyz="0 0 0" rpy="0 0 0"/>
        <geometry>
          <cylinder radius="0.015" length="0.06"/>
        </geometry>
        <material name="Material.034"/>
      </visual>
    </link>

    <link name="Untitled.085">
      <inertial>
        <origin xyz="0 0 0" rpy="0 0 0"/>
        <mass value="0.001"/>
        <inertia ixx="0.001" ixy="0" ixz="0" iyy="0.001" iyz="0" izz="0.001"/>
      </inertial>
      <visual name="DC Motor.003">
        <origin xyz="0 0 0" rpy="0 0 0"/>
        <geometry>
          <mesh filename="DC Motor.stl" scale="0.00227 0.00227 0.00133"/>
        </geometry>
        <material name="Material.052"/>
      </visual>
    </link>

    <link name="Untitled.086">
      <inertial>
        <origin xyz="0 0 0" rpy="0 0 0"/>
        <mass value="0.001"/>
        <inertia ixx="0.001" ixy="0" ixz="0" iyy="0.001" iyz="0" izz="0.001"/>
      </inertial>
      <visual name="DC Motor">
        <origin xyz="0 0 0" rpy="0 0 0"/>
        <geometry>
          <mesh filename="DC Motor.stl" scale="0.00227 0.00227 0.00133"/>
        </geometry>
        <material name="Material.052"/>
      </visual>
    </link>

    <link name="Untitled.087">
      <inertial>
        <origin xyz="0 0 0" rpy="0 0 0"/>
        <mass value="0.001"/>
        <inertia ixx="0.001" ixy="0" ixz="0" iyy="0.001" iyz="0" izz="0.001"/>
      </inertial>
      <visual name="DC Motor.001">
        <origin xyz="0 0 0" rpy="0 0 0"/>
        <geometry>
          <mesh filename="DC Motor.stl" scale="0.00227 0.00227 0.00133"/>
        </geometry>
        <material name="Material.052"/>
      </visual>
    </link>

    <link name="Untitled.088">
      <inertial>
        <origin xyz="0 0 0" rpy="0 0 0"/>
        <mass value="0.001"/>
        <inertia ixx="0.001" ixy="0" ixz="0" iyy="0.001" iyz="0" izz="0.001"/>
      </inertial>
      <visual name="DC Motor.002">
        <origin xyz="0 0 0" rpy="0 0 0"/>
        <geometry>
          <mesh filename="DC Motor.stl" scale="0.00227 0.00227 0.00133"/>
        </geometry>
        <material name="Material.052"/>
      </visual>
    </link>

    <link name="Untitled.089">
      <inertial>
        <origin xyz="0 0 0" rpy="0 0 0"/>
        <mass value="0.001"/>
        <inertia ixx="0.001" ixy="0" ixz="0" iyy="0.001" iyz="0" izz="0.001"/>
      </inertial>
      <visual name="DC Motor.007">
        <origin xyz="0 0 0" rpy="0 0 0"/>
        <geometry>
          <mesh filename="DC Motor.stl" scale="0.00227 0.00227 0.00133"/>
        </geometry>
        <material name="Material.052"/>
      </visual>
    </link>

    <link name="Untitled.090">
      <inertial>
        <origin xyz="0 0 0" rpy="0 0 0"/>
        <mass value="0.001"/>
        <inertia ixx="0.001" ixy="0" ixz="0" iyy="0.001" iyz="0" izz="0.001"/>
      </inertial>
      <visual name="DC Motor.004">
        <origin xyz="0 0 0" rpy="0 0 0"/>
        <geometry>
          <mesh filename="DC Motor.stl" scale="0.00227 0.00227 0.00133"/>
        </geometry>
        <material name="Material.052"/>
      </visual>
    </link>

    <link name="Untitled.091">
      <inertial>
        <origin xyz="0 0 0" rpy="0 0 0"/>
        <mass value="0.001"/>
        <inertia ixx="0.001" ixy="0" ixz="0" iyy="0.001" iyz="0" izz="0.001"/>
      </inertial>
      <visual name="DC Motor.005">
        <origin xyz="0 0 0" rpy="0 0 0"/>
        <geometry>
          <mesh filename="DC Motor.stl" scale="0.00227 0.00227 0.00133"/>
        </geometry>
        <material name="Material.052"/>
      </visual>
    </link>

    <link name="Untitled.092">
      <inertial>
        <origin xyz="0 0 0" rpy="0 0 0"/>
        <mass value="0.001"/>
        <inertia ixx="0.001" ixy="0" ixz="0" iyy="0.001" iyz="0" izz="0.001"/>
      </inertial>
      <visual name="DC Motor.006">
        <origin xyz="0 0 0" rpy="0 0 0"/>
        <geometry>
          <mesh filename="DC Motor.stl" scale="0.00227 0.00227 0.00133"/>
        </geometry>
        <material name="Material.052"/>
      </visual>
    </link>

    <link name="Untitled.093">
      <inertial>
        <origin xyz="0 0 0" rpy="0 0 0"/>
        <mass value="0.001"/>
        <inertia ixx="0.001" ixy="0" ixz="0" iyy="0.001" iyz="0" izz="0.001"/>
      </inertial>
      <visual name="NEMA 17.001">
        <origin xyz="0 0 0" rpy="0 0 0"/>
        <geometry>
          <mesh filename="NEMA 17.001.stl" scale="0.00099 0.00099 0.00059"/>
        </geometry>
        <material name="Material.048"/>
      </visual>
    </link>

    <link name="Untitled.094">
      <inertial>
        <origin xyz="0 0 0" rpy="0 0 0"/>
        <mass value="0.001"/>
        <inertia ixx="0.001" ixy="0" ixz="0" iyy="0.001" iyz="0" izz="0.001"/>
      </inertial>
      <visual name="NEMA 17.002">
        <origin xyz="0 0 0" rpy="0 0 0"/>
        <geometry>
          <mesh filename="NEMA 17.002.stl" scale="0.00099 0.00099 0.00059"/>
        </geometry>
        <material name="Material.049"/>
      </visual>
    </link>

    <link name="Untitled.095">
      <inertial>
        <origin xyz="0 0 0" rpy="0 0 0"/>
        <mass value="0.001"/>
        <inertia ixx="0.001" ixy="0" ixz="0" iyy="0.001" iyz="0" izz="0.001"/>
      </inertial>
      <visual name="16gear">
        <origin xyz="0 0 0" rpy="0 0 0"/>
        <geometry>
          <mesh filename="16gear.stl" scale="0.00053 0.00053 0.001"/>
        </geometry>
      </visual>
    </link>

    <link name="Untitled.096">
      <inertial>
        <origin xyz="0 0 0" rpy="0 0 0"/>
        <mass value="0.001"/>
        <inertia ixx="0.001" ixy="0" ixz="0" iyy="0.001" iyz="0" izz="0.001"/>
      </inertial>
      <visual name="rack">
        <origin xyz="-0.15 0 0" rpy="0 0 0"/>
        <geometry>
          <mesh filename="rack.stl" scale="0.00089 0.00136 0.004"/>
        </geometry>
        <material name="Material.050"/>
      </visual>
    </link>

    <link name="Untitled.097">
      <inertial>
        <origin xyz="0 0 0" rpy="0 0 0"/>
        <mass value="0.001"/>
        <inertia ixx="0.001" ixy="0" ixz="0" iyy="0.001" iyz="0" izz="0.001"/>
      </inertial>
      <visual name="bl Link.002.002">
        <origin xyz="0 -0.0024 0.005" rpy="0 3.14159 0"/>
        <geometry>
          <mesh filename="Cylinder.003.stl" scale="0.77778 0.77778 1.0"/>
        </geometry>
        <material name="Material.001"/>
      </visual>
    </link>

    <link name="Untitled.098">
      <inertial>
        <origin xyz="0 0 0" rpy="0 0 0"/>
        <mass value="0.001"/>
        <inertia ixx="0.001" ixy="0" ixz="0" iyy="0.001" iyz="0" izz="0.001"/>
      </inertial>
      <visual name="bl Link.002.005">
        <origin xyz="0 -0.0024 -0.005" rpy="0 0 0"/>
        <geometry>
          <mesh filename="Cylinder.003.stl" scale="0.77778 0.77778 1.0"/>
        </geometry>
        <material name="Material.001"/>
      </visual>
    </link>

    <link name="Untitled.099">
      <inertial>
        <origin xyz="0 0 0" rpy="0 0 0"/>
        <mass value="0.001"/>
        <inertia ixx="0.001" ixy="0" ixz="0" iyy="0.001" iyz="0" izz="0.001"/>
      </inertial>
      <visual name="bl Link.002.004">
        <origin xyz="0 -0.0024 0.005" rpy="0 3.14159 0"/>
        <geometry>
          <mesh filename="Cylinder.003.stl" scale="0.77778 0.77778 1.0"/>
        </geometry>
        <material name="Material.001"/>
      </visual>
    </link>

    <link name="Untitled.100">
      <inertial>
        <origin xyz="0 0 0" rpy="0 0 0"/>
        <mass value="0.001"/>
        <inertia ixx="0.001" ixy="0" ixz="0" iyy="0.001" iyz="0" izz="0.001"/>
      </inertial>
      <visual name="bl Link.002.003">
        <origin xyz="0 -0.0024 0.005" rpy="0 0 0"/>
        <geometry>
          <mesh filename="Cylinder.003.stl" scale="0.77778 0.77778 1.0"/>
        </geometry>
        <material name="Material.001"/>
      </visual>
    </link>

    <link name="Untitled.101">
      <inertial>
        <origin xyz="0 0 0" rpy="0 0 0"/>
        <mass value="0.001"/>
        <inertia ixx="0.001" ixy="0" ixz="0" iyy="0.001" iyz="0" izz="0.001"/>
      </inertial>
      <visual name="motoreducteur">
        <origin xyz="0 0 0" rpy="0 0 0"/>
        <geometry>
          <mesh filename="motoreducteur.stl" scale="0.00114 0.00446 0.00157"/>
        </geometry>
        <material name="Material.023"/>
      </visual>
    </link>

    <link name="Untitled.102">
      <inertial>
        <origin xyz="0 0 0" rpy="0 0 0"/>
        <mass value="0.001"/>
        <inertia ixx="0.001" ixy="0" ixz="0" iyy="0.001" iyz="0" izz="0.001"/>
      </inertial>
      <visual name="Cylinder.014">
        <origin xyz="0.03 0 0" rpy="0 0 0"/>
        <geometry>
          <cylinder radius="0.005" length="0.23"/>
        </geometry>
        <material name="Material.024"/>
      </visual>
    </link>

    <link name="Untitled.104">
      <inertial>
        <origin xyz="0 0 0" rpy="0 0 0"/>
        <mass value="0.001"/>
        <inertia ixx="0.001" ixy="0" ixz="0" iyy="0.001" iyz="0" izz="0.001"/>
      </inertial>
      <visual name="motoreducteur.001">
        <origin xyz="0 0 0" rpy="0 0 0"/>
        <geometry>
          <mesh filename="motoreducteur.stl" scale="0.00114 0.00446 0.00157"/>
        </geometry>
        <material name="Material.023"/>
      </visual>
    </link>

    <link name="Untitled.105">
      <inertial>
        <origin xyz="0 0 0" rpy="0 0 0"/>
        <mass value="0.001"/>
        <inertia ixx="0.001" ixy="0" ixz="0" iyy="0.001" iyz="0" izz="0.001"/>
      </inertial>
      <visual name="Cylinder.015">
        <origin xyz="0.03 0 0" rpy="0 0 0"/>
        <geometry>
          <cylinder radius="0.005" length="0.23"/>
        </geometry>
        <material name="Material.024"/>
      </visual>
    </link>

    <link name="Untitled.106">
      <inertial>
        <origin xyz="0 0 0" rpy="0 0 0"/>
        <mass value="0.001"/>
        <inertia ixx="0.001" ixy="0" ixz="0" iyy="0.001" iyz="0" izz="0.001"/>
      </inertial>
      <visual name="L bracket.015">
        <origin xyz="-0.025 0 0" rpy="0 0 0"/>
        <geometry>
          <mesh filename="L bracket.stl" scale="0.00116 0.0016 0.00167"/>
        </geometry>
        <material name="Material.051"/>
      </visual>
    </link>

    <link name="Untitled.107">
      <inertial>
        <origin xyz="0 0 0" rpy="0 0 0"/>
        <mass value="0.001"/>
        <inertia ixx="0.001" ixy="0" ixz="0" iyy="0.001" iyz="0" izz="0.001"/>
      </inertial>
      <visual name="L bracket.012">
        <origin xyz="0 0 -0.03" rpy="0 0 0"/>
        <geometry>
          <mesh filename="L bracket.stl" scale="0.00116 0.0016 0.00167"/>
        </geometry>
        <material name="Material.051"/>
      </visual>
    </link>

    <link name="Untitled.108">
      <inertial>
        <origin xyz="0 0 0" rpy="0 0 0"/>
        <mass value="0.001"/>
        <inertia ixx="0.001" ixy="0" ixz="0" iyy="0.001" iyz="0" izz="0.001"/>
      </inertial>
      <visual name="L bracket.013">
        <origin xyz="0.02 0 0" rpy="0 0 0"/>
        <geometry>
          <mesh filename="L bracket.stl" scale="0.00116 0.0016 0.00167"/>
        </geometry>
        <material name="Material.051"/>
      </visual>
    </link>

    <link name="Untitled.109">
      <inertial>
        <origin xyz="0 0 0" rpy="0 0 0"/>
        <mass value="0.001"/>
        <inertia ixx="0.001" ixy="0" ixz="0" iyy="0.001" iyz="0" izz="0.001"/>
      </inertial>
      <visual name="L bracket.014">
        <origin xyz="0 0 0.02367" rpy="0 0 0"/>
        <geometry>
          <mesh filename="L bracket.stl" scale="0.00116 0.0016 0.00167"/>
        </geometry>
        <material name="Material.051"/>
      </visual>
    </link>

    <link name="Untitled.110">
      <inertial>
        <origin xyz="0 0 0" rpy="0 0 0"/>
        <mass value="0.2"/>
        <inertia ixx="2e-05" ixy="0" ixz="0" iyy="2e-05" iyz="0" izz="2e-05"/>
      </inertial>
      <visual name="Cube.016">
        <origin xyz="0 0 0" rpy="0 0 0"/>
        <geometry>
          <box size="0.23 0.1 0.06"/>
        </geometry>
        <material name="Material.021"/>
      </visual>
      <visual name="vertical rod">
        <origin xyz="0.16779 0.00101 -1.52241" rpy="1.5708 0 0"/>
        <geometry>
          <mesh filename="vertical rod.004.stl" scale="1.0 1.0 1.0"/>
        </geometry>
        <material name="Material.022"/>
      </visual>
      <visual name="vertical rod.001">
        <origin xyz="-0.16721 0.00101 -1.52241" rpy="1.5708 0 0"/>
        <geometry>
          <mesh filename="vertical rod.004.stl" scale="1.0 1.0 1.0"/>
        </geometry>
        <material name="Material.022"/>
      </visual>
      <collision name="Cube.016">
        <origin xyz="0 0 0" rpy="0 0 0"/>
        <geometry>
          <box size="0.23 0.1 0.06"/>
        </geometry>
      </collision>
      <collision name="vertical rod.000.001">
        <origin xyz="0.16779 0.00101 -1.52241" rpy="1.5708 0 0"/>
        <geometry>
          <mesh filename="vertical rod.008.stl" scale="1.0 1.0 1.0"/>
        </geometry>
      </collision>
      <collision name="vertical rod.001.000.001">
        <origin xyz="-0.16721 0.00101 -1.52241" rpy="1.5708 0 0"/>
        <geometry>
          <mesh filename="vertical rod.007.stl" scale="1.0 1.0 1.0"/>
        </geometry>
      </collision>
    </link>

    <link name="Untitled.111">
      <inertial>
        <origin xyz="0 0 0" rpy="0 0 0"/>
        <mass value="0.2"/>
        <inertia ixx="2e-05" ixy="0" ixz="0" iyy="2e-05" iyz="0" izz="2e-05"/>
      </inertial>
      <visual name="Cube.017">
        <origin xyz="0 0 0" rpy="0 0 0"/>
        <geometry>
          <box size="0.23 0.1 0.06"/>
        </geometry>
        <material name="Material.021"/>
      </visual>
      <visual name="vertical rod.002">
        <origin xyz="-0.16721 0.00101 -1.52241" rpy="1.5708 0 0"/>
        <geometry>
          <mesh filename="vertical rod.004.stl" scale="1.0 1.0 1.0"/>
        </geometry>
        <material name="Material.022"/>
      </visual>
      <visual name="vertical rod.003">
        <origin xyz="0.16779 0.00101 -1.52241" rpy="1.5708 0 0"/>
        <geometry>
          <mesh filename="vertical rod.004.stl" scale="1.0 1.0 1.0"/>
        </geometry>
        <material name="Material.022"/>
      </visual>
      <collision name="Cube.017">
        <origin xyz="0 0 0.01" rpy="0 0 0"/>
        <geometry>
          <box size="0.23 0.1 0.05"/>
        </geometry>
      </collision>
      <collision name="vertical rod.002.000">
        <origin xyz="-0.16721 0.00101 -0.75241" rpy="1.5708 0 0"/>
        <geometry>
          <mesh filename="vertical rod.006.stl" scale="1.0 1.0 1.0"/>
        </geometry>
      </collision>
      <collision name="vertical rod.003.000">
        <origin xyz="0.16779 0.00101 -1.52241" rpy="1.5708 0 0"/>
        <geometry>
          <mesh filename="vertical rod.005.stl" scale="1.0 1.0 1.0"/>
        </geometry>
      </collision>
    </link>

    <link name="Untitled.112">
      <inertial>
        <origin xyz="0 0 0" rpy="0 0 0"/>
        <mass value="0.001"/>
        <inertia ixx="0.001" ixy="0" ixz="0" iyy="0.001" iyz="0" izz="0.001"/>
      </inertial>
      <visual name="Cube.018">
        <origin xyz="0 0 0" rpy="0 0 0"/>
        <geometry>
          <box size="0.03 0.1 0.12"/>
        </geometry>
        <material name="Material.028"/>
      </visual>
    </link>

    <link name="Untitled.113">
      <inertial>
        <origin xyz="0 0 0" rpy="0 0 0"/>
        <mass value="0.001"/>
        <inertia ixx="0.001" ixy="0" ixz="0" iyy="0.001" iyz="0" izz="0.001"/>
      </inertial>
      <visual name="Cube.019">
        <origin xyz="0.05 0 0" rpy="0 0 0"/>
        <geometry>
          <box size="0.23 0.23 0.01"/>
        </geometry>
        <material name="Material.029"/>
      </visual>
    </link>

    <link name="Untitled.114">
      <inertial>
        <origin xyz="0 0 0" rpy="0 0 0"/>
        <mass value="0.001"/>
        <inertia ixx="0.001" ixy="0" ixz="0" iyy="0.001" iyz="0" izz="0.001"/>
      </inertial>
      <visual name="Aruco">
        <origin xyz="0 0 0" rpy="0 0 0"/>
        <geometry>
          <mesh filename="Aruco.stl" scale="0.0032 0.002 0.0032"/>
        </geometry>
        <material name="Material.031"/>
      </visual>
    </link>

    <link name="Untitled.115">
      <inertial>
        <origin xyz="0 0 0" rpy="0 0 0"/>
        <mass value="0.001"/>
        <inertia ixx="0.001" ixy="0" ixz="0" iyy="0.001" iyz="0" izz="0.001"/>
      </inertial>
      <visual name="Cube.020">
        <origin xyz="0 0 0" rpy="0 0 0"/>
        <geometry>
          <box size="0.04 0.07 0.005"/>
        </geometry>
        <material name="Material.043"/>
      </visual>
    </link>

    <link name="Untitled.116">
      <inertial>
        <origin xyz="0 0 0" rpy="0 0 0"/>
        <mass value="0.001"/>
        <inertia ixx="0.001" ixy="0" ixz="0" iyy="0.001" iyz="0" izz="0.001"/>
      </inertial>
      <visual name="Cube.021">
        <origin xyz="0 0 -0.07" rpy="0 0 0"/>
        <geometry>
          <box size="0.2 0.01 0.2"/>
        </geometry>
        <material name="Material.044"/>
      </visual>
    </link>

    <link name="Untitled.117">
      <inertial>
        <origin xyz="0 0 0" rpy="0 0 0"/>
        <mass value="0.001"/>
        <inertia ixx="0.001" ixy="0" ixz="0" iyy="0.001" iyz="0" izz="0.001"/>
      </inertial>
      <visual name="Aruco.001">
        <origin xyz="0 -0.05 0" rpy="0 0 0"/>
        <geometry>
          <mesh filename="Aruco.001.stl" scale="0.0028 0.002 0.0028"/>
        </geometry>
        <material name="Material.045"/>
      </visual>
    </link>

    <link name="Untitled.118">
      <inertial>
        <origin xyz="0 0 0" rpy="0 0 0"/>
        <mass value="0.001"/>
        <inertia ixx="0.001" ixy="0" ixz="0" iyy="0.001" iyz="0" izz="0.001"/>
      </inertial>
      <visual name="12">
        <origin xyz="-7e-05 0.003 0.001" rpy="-1.5708 0 0"/>
        <geometry>
          <mesh filename="12.stl" scale="0.00724 0.00677 0.00094"/>
        </geometry>
        <material name="Material.054"/>
      </visual>
    </link>

    <link name="Untitled.119">
      <inertial>
        <origin xyz="0 0 0" rpy="0 0 0"/>
        <mass value="0.001"/>
        <inertia ixx="0.001" ixy="0" ixz="0" iyy="0.001" iyz="0" izz="0.001"/>
      </inertial>
      <visual name="12.001">
        <origin xyz="-7e-05 -0.003 0.001" rpy="1.5708 0 0"/>
        <geometry>
          <mesh filename="12.001.stl" scale="0.00724 0.00677 0.00094"/>
        </geometry>
        <material name="Material.053"/>
      </visual>
    </link>

    <joint name="Untitled" type="fixed">
      <origin xyz="-0.11 0.06 0" rpy="1.5708 0 0"/>
      <parent link="Untitled.004"/>
      <child link="Untitled"/>
    </joint>

    <joint name="Untitled.001" type="fixed">
      <origin xyz="-0.11 -0.06 0" rpy="-1.5708 0 0"/>
      <parent link="Untitled.004"/>
      <child link="Untitled.001"/>
    </joint>

    <joint name="Untitled.002" type="fixed">
      <origin xyz="0.11 0.06 0" rpy="1.5708 0 0"/>
      <parent link="Untitled.004"/>
      <child link="Untitled.002"/>
    </joint>

    <joint name="Untitled.003" type="fixed">
      <origin xyz="0.11 -0.06 0" rpy="-1.5708 0 0"/>
      <parent link="Untitled.004"/>
      <child link="Untitled.003"/>
    </joint>

    <joint name="Untitled.004" type="fixed">
      <origin xyz="0.00279 0.00101 -1.57241" rpy="0 0 0"/>
      <parent link="Untitled.110"/>
      <child link="Untitled.004"/>
    </joint>

    <joint name="Untitled.005" type="continuous">
      <origin xyz="0.04 0 -0.07" rpy="3.14159 0 0"/>
      <parent link="Untitled.002"/>
      <child link="Untitled.005"/>
      <axis xyz="0 0 1.0"/>
      <limit effort="0.1" velocity="1.5"/>
    </joint>

    <joint name="Untitled.006" type="continuous">
      <origin xyz="-0.04 0 -0.07" rpy="3.14159 0 0"/>
      <parent link="Untitled"/>
      <child link="Untitled.006"/>
      <axis xyz="0 0 1.0"/>
      <limit effort="0.1" velocity="1.5"/>
    </joint>

    <joint name="Untitled.007" type="continuous">
      <origin xyz="-0.04 0 -0.07" rpy="-3.14159 0 0"/>
      <parent link="Untitled.001"/>
      <child link="Untitled.007"/>
      <axis xyz="0 0 1.0"/>
      <limit effort="0.1" velocity="1.5"/>
    </joint>

    <joint name="Untitled.008" type="continuous">
      <origin xyz="0.04 0 -0.07" rpy="-3.14159 0 0"/>
      <parent link="Untitled.003"/>
      <child link="Untitled.008"/>
      <axis xyz="0 0 1.0"/>
      <limit effort="0.1" velocity="1.5"/>
    </joint>

    <joint name="Untitled.009" type="fixed">
      <origin xyz="0.00279 -0.00399 -1.57241" rpy="0 0 0"/>
      <parent link="Untitled.111"/>
      <child link="Untitled.009"/>
    </joint>

    <joint name="Untitled.010" type="fixed">
      <origin xyz="-0.11 -0.06 0" rpy="-1.5708 0 0"/>
      <parent link="Untitled.009"/>
      <child link="Untitled.010"/>
    </joint>

    <joint name="Untitled.011" type="continuous">
      <origin xyz="-0.04 0 -0.07" rpy="-3.14159 0 0"/>
      <parent link="Untitled.010"/>
      <child link="Untitled.011"/>
      <axis xyz="0 0 1.0"/>
      <limit effort="0.1" velocity="1.5"/>
    </joint>

    <joint name="Untitled.012" type="fixed">
      <origin xyz="-0.11 0.06 0" rpy="1.5708 0 0"/>
      <parent link="Untitled.009"/>
      <child link="Untitled.012"/>
    </joint>

    <joint name="Untitled.013" type="fixed">
      <origin xyz="0 0 0.055" rpy="0 0 0"/>
      <parent link="Untitled.053"/>
      <child link="Untitled.013"/>
    </joint>

    <joint name="Untitled.014" type="fixed">
      <origin xyz="0.11 0.06 0" rpy="1.5708 0 0"/>
      <parent link="Untitled.009"/>
      <child link="Untitled.014"/>
    </joint>

    <joint name="Untitled.015" type="continuous">
      <origin xyz="0.04 0 -0.07" rpy="3.14159 0 0"/>
      <parent link="Untitled.014"/>
      <child link="Untitled.015"/>
      <axis xyz="0 0 1.0"/>
      <limit effort="0.1" velocity="1.5"/>
    </joint>

    <joint name="Untitled.016" type="fixed">
      <origin xyz="0.11 -0.06 0" rpy="-1.5708 0 0"/>
      <parent link="Untitled.009"/>
      <child link="Untitled.016"/>
    </joint>

    <joint name="Untitled.017" type="continuous">
      <origin xyz="0.04 0 -0.07" rpy="-3.14159 0 0"/>
      <parent link="Untitled.016"/>
      <child link="Untitled.017"/>
      <axis xyz="0 0 1.0"/>
      <limit effort="0.1" velocity="1.5"/>
    </joint>

    <joint name="Untitled.018" type="fixed">
      <origin xyz="0 0.04 -0.04" rpy="0 0 0"/>
      <parent link="Untitled.047"/>
      <child link="Untitled.018"/>
    </joint>

    <joint name="Untitled.019" type="prismatic">
      <origin xyz="0 0 -0.01039" rpy="0 0 0"/>
      <parent link="Untitled.018"/>
      <child link="Untitled.019"/>
      <axis xyz="0 0 1.0"/>
      <limit lower="-1.6" upper="1.6" effort="0.01" velocity="0.1"/>
    </joint>

    <joint name="Untitled.020" type="fixed">
      <origin xyz="0 -0.00117 -0.05884" rpy="0 0 0"/>
      <parent link="Untitled.019"/>
      <child link="Untitled.020"/>
    </joint>

    <joint name="Untitled.021" type="fixed">
      <origin xyz="0.06656 -0.00819 -0.00718" rpy="0 0 0"/>
      <parent link="Untitled.024"/>
      <child link="Untitled.021"/>
    </joint>

    <joint name="Untitled.022" type="fixed">
      <origin xyz="-0.06 -0.05371 0" rpy="-1.5708 0 0"/>
      <parent link="Untitled.026"/>
      <child link="Untitled.022"/>
    </joint>

    <joint name="Untitled.023" type="fixed">
      <origin xyz="0.06 -0.05371 0" rpy="-1.5708 0 0"/>
      <parent link="Untitled.026"/>
      <child link="Untitled.023"/>
    </joint>

    <joint name="Untitled.024" type="fixed">
      <origin xyz="-0.00656 0.00819 -0.03142" rpy="0 0 0"/>
      <parent link="Untitled.022"/>
      <child link="Untitled.024"/>
    </joint>

    <joint name="Untitled.025" type="fixed">
      <origin xyz="0.00237 -0.00899 -0.03609" rpy="0 0 0"/>
      <parent link="Untitled.023"/>
      <child link="Untitled.025"/>
    </joint>

    <joint name="Untitled.026" type="prismatic">
      <origin xyz="0.025 0 0.04555" rpy="1.5708 0 -1.5708"/>
      <parent link="Untitled.052"/>
      <child link="Untitled.026"/>
      <axis xyz="0 0 1.0"/>
      <limit lower="-1.2931" upper="1.29" effort="0.1" velocity="1.0"/>
    </joint>

    <joint name="Untitled.027" type="fixed">
      <origin xyz="0.00656 -0.00819 -0.15126" rpy="0 0 0"/>
      <parent link="Untitled.024"/>
      <child link="Untitled.027"/>
    </joint>

    <joint name="Untitled.028" type="prismatic">
      <origin xyz="0 0 -0.02468" rpy="0 0 0"/>
      <parent link="Untitled.027"/>
      <child link="Untitled.028"/>
      <axis xyz="0 0 1.0"/>
      <limit lower="-1.2931" upper="1.29" effort="0.1" velocity="1.0"/>
    </joint>

    <joint name="Untitled.029" type="fixed">
      <origin xyz="0.01 0 -0.12848" rpy="0 0 0"/>
      <parent link="Untitled.028"/>
      <child link="Untitled.029"/>
    </joint>

    <joint name="Untitled.030" type="fixed">
      <origin xyz="0.05 0 0.14075" rpy="0 0 0"/>
      <parent link="Untitled.029"/>
      <child link="Untitled.030"/>
    </joint>

    <joint name="Untitled.031" type="prismatic">
      <origin xyz="0 0 -0.02247" rpy="0 0 0"/>
      <parent link="Untitled.030"/>
      <child link="Untitled.031"/>
      <axis xyz="0 0 1.0"/>
      <limit lower="-1.2931" upper="1.29" effort="0.1" velocity="1.0"/>
    </joint>

    <joint name="Untitled.032" type="fixed">
      <origin xyz="0.00738 0.0014 -0.1528" rpy="0 0 0"/>
      <parent link="Untitled.031"/>
      <child link="Untitled.032"/>
    </joint>

    <joint name="Untitled.033" type="fixed">
      <origin xyz="0.05262 -0.0014 0.13993" rpy="0 0 0"/>
      <parent link="Untitled.032"/>
      <child link="Untitled.033"/>
    </joint>

    <joint name="Untitled.034" type="prismatic">
      <origin xyz="0 0 -0.01" rpy="0 0 0"/>
      <parent link="Untitled.033"/>
      <child link="Untitled.034"/>
      <axis xyz="0 0 1.0"/>
      <limit lower="-1.2931" upper="1.29" effort="0.1" velocity="1.0"/>
    </joint>

    <joint name="Untitled.035" type="fixed">
      <origin xyz="0.00989 -0.00047 -0.15397" rpy="0 0 0"/>
      <parent link="Untitled.034"/>
      <child link="Untitled.035"/>
    </joint>

    <joint name="Untitled.036" type="continuous">
      <origin xyz="-0.00332 0.00214 -0.04292" rpy="0 0 0"/>
      <parent link="Untitled.035"/>
      <child link="Untitled.036"/>
      <axis xyz="0 0 1.0"/>
      <limit effort="0.1" velocity="1.0"/>
    </joint>

    <joint name="Untitled.037" type="fixed">
      <origin xyz="0 -0.0625 -0.09126" rpy="1.5708 0 0"/>
      <parent link="Untitled.036"/>
      <child link="Untitled.037"/>
    </joint>

    <joint name="Untitled.038" type="prismatic">
      <origin xyz="0 0.0825 -0.09126" rpy="1.5708 0 0"/>
      <parent link="Untitled.036"/>
      <child link="Untitled.038"/>
      <axis xyz="0 0 1.0"/>
      <limit lower="-1.6" upper="1.6" effort="0.1" velocity="0.05"/>
    </joint>

    <joint name="Untitled.039" type="fixed">
      <origin xyz="-0.175 0.03 0.0476" rpy="1.5708 0 1.5708"/>
      <parent link="Untitled.009"/>
      <child link="Untitled.039"/>
    </joint>

    <joint name="Untitled.040" type="fixed">
      <origin xyz="-0.195 -0.02 0.0476" rpy="1.5708 0 -3.14159"/>
      <parent link="Untitled.009"/>
      <child link="Untitled.040"/>
    </joint>

    <joint name="Untitled.041" type="fixed">
      <origin xyz="0.04032 -0.00214 -0.00337" rpy="0 0 0"/>
      <parent link="Untitled.036"/>
      <child link="Untitled.041"/>
    </joint>

    <joint name="Untitled.042" type="revolute">
      <origin xyz="0.03 0.01 0.00027" rpy="1.5708 0 0"/>
      <parent link="Untitled.041"/>
      <child link="Untitled.042"/>
      <axis xyz="0 0 1.0"/>
      <limit lower="-1.57" upper="0" effort="0.01" velocity="0.1"/>
    </joint>

    <joint name="Untitled.043" type="fixed">
      <origin xyz="0.002 0 0.02" rpy="-1.5708 0 -1.5708"/>
      <parent link="Untitled.042"/>
      <child link="Untitled.043"/>
    </joint>

    <joint name="Untitled.044" type="fixed">
      <origin xyz="0.002 0 0" rpy="-1.5708 0 -1.5708"/>
      <parent link="Untitled.042"/>
      <child link="Untitled.044"/>
    </joint>

    <joint name="Untitled.045" type="fixed">
      <origin xyz="0.19 0.03 0.0476" rpy="1.5708 0 0"/>
      <parent link="Untitled.009"/>
      <child link="Untitled.045"/>
    </joint>

    <joint name="Untitled.046" type="fixed">
      <origin xyz="0.19 -0.02 0.0476" rpy="1.5708 0 -1.5708"/>
      <parent link="Untitled.009"/>
      <child link="Untitled.046"/>
    </joint>

    <joint name="Untitled.047" type="fixed">
      <origin xyz="0 0.1 0" rpy="0 0 0"/>
      <parent link="Untitled.036"/>
      <child link="Untitled.047"/>
    </joint>

    <joint name="Untitled.048" type="fixed">
      <origin xyz="0.10668 -8e-05 0.01932" rpy="0 0 0"/>
      <parent link="Untitled.110"/>
      <child link="Untitled.048"/>
    </joint>

    <joint name="Untitled.049" type="fixed">
      <origin xyz="0.00415 -0.00265 0.05003" rpy="0 0 0"/>
      <parent link="Untitled.048"/>
      <child link="Untitled.049"/>
    </joint>

    <joint name="Untitled.050" type="fixed">
      <origin xyz="0.15 -0.02 0.0476" rpy="1.5708 0 -3.14159"/>
      <parent link="Untitled.009"/>
      <child link="Untitled.050"/>
    </joint>

    <joint name="Untitled.051" type="fixed">
      <origin xyz="0.14 0.03 0.0476" rpy="1.5708 0 1.5708"/>
      <parent link="Untitled.009"/>
      <child link="Untitled.051"/>
    </joint>

    <joint name="Untitled.053" type="fixed">
      <origin xyz="-0.02833 0 0.05969" rpy="0 -1.5708 0"/>
      <parent link="Untitled.049"/>
      <child link="Untitled.053"/>
    </joint>

    <joint name="Untitled.054" type="continuous">
      <origin xyz="-0.04 0 -0.07" rpy="3.14159 0 0"/>
      <parent link="Untitled.012"/>
      <child link="Untitled.054"/>
      <axis xyz="0 0 1.0"/>
      <limit effort="0.1" velocity="1.5"/>
    </joint>

    <joint name="Untitled.055" type="fixed">
      <origin xyz="0 0 0.08" rpy="0 3.14159 0"/>
      <parent link="Untitled.013"/>
      <child link="Untitled.055"/>
    </joint>

    <joint name="Untitled.056" type="fixed">
      <origin xyz="0.05 0 -0.04" rpy="0 -1.5708 0"/>
      <parent link="Untitled.055"/>
      <child link="Untitled.056"/>
    </joint>

    <joint name="Untitled.057" type="fixed">
      <origin xyz="-0.07251 -0.00274 0.02904" rpy="0 1.5708 0"/>
      <parent link="Untitled.110"/>
      <child link="Untitled.057"/>
    </joint>

    <joint name="Untitled.058" type="fixed">
      <origin xyz="-0.00145 1.25375 0.0247" rpy="3.14159 0 1.5708"/>
      <parent link="Untitled.013"/>
      <child link="Untitled.058"/>
    </joint>

    <joint name="Untitled.059" type="fixed">
      <origin xyz="0.05809 0.00726 -0.01033" rpy="0 1.5708 0"/>
      <parent link="Untitled.111"/>
      <child link="Untitled.059"/>
    </joint>

    <joint name="Untitled.060" type="fixed">
      <origin xyz="-0.04812 0 0.04" rpy="0 -1.5708 0"/>
      <parent link="Untitled.059"/>
      <child link="Untitled.060"/>
    </joint>

    <joint name="Untitled.061" type="fixed">
      <origin xyz="-0.04 0 0.05125" rpy="0 1.5708 0"/>
      <parent link="Untitled.060"/>
      <child link="Untitled.061"/>
    </joint>

    <joint name="Untitled.062" type="fixed">
      <origin xyz="0 0 0.0194" rpy="0 -3.14159 0"/>
      <parent link="Untitled.061"/>
      <child link="Untitled.062"/>
    </joint>

    <joint name="Untitled.063" type="fixed">
      <origin xyz="0 -0.00625 0.13" rpy="0 3.14159 0"/>
      <parent link="Untitled.062"/>
      <child link="Untitled.063"/>
    </joint>

    <joint name="Untitled.064" type="fixed">
      <origin xyz="0.05 0 -0.04" rpy="0 -1.5708 0"/>
      <parent link="Untitled.063"/>
      <child link="Untitled.064"/>
    </joint>

    <joint name="Untitled.065" type="fixed">
      <origin xyz="-0.05251 0.00101 -0.01107" rpy="0 1.5708 0"/>
      <parent link="Untitled.111"/>
      <child link="Untitled.065"/>
    </joint>

    <joint name="Untitled.073" type="fixed">
      <origin xyz="-0.145 -0.02 0.0476" rpy="1.5708 0 -1.5708"/>
      <parent link="Untitled.009"/>
      <child link="Untitled.073"/>
    </joint>

    <joint name="Untitled.074" type="fixed">
      <origin xyz="-0.15 0.03 0.0476" rpy="1.5708 0 0"/>
      <parent link="Untitled.009"/>
      <child link="Untitled.074"/>
    </joint>

    <joint name="Untitled.075" type="fixed">
      <origin xyz="-0.195 0.025 0.06" rpy="1.5708 0 1.5708"/>
      <parent link="Untitled.004"/>
      <child link="Untitled.075"/>
    </joint>

    <joint name="Untitled.076" type="fixed">
      <origin xyz="-0.195 -0.025 0.06" rpy="1.5708 0 -3.14159"/>
      <parent link="Untitled.004"/>
      <child link="Untitled.076"/>
    </joint>

    <joint name="Untitled.077" type="fixed">
      <origin xyz="-0.155 -0.025 0.06" rpy="1.5708 0 -1.5708"/>
      <parent link="Untitled.004"/>
      <child link="Untitled.077"/>
    </joint>

    <joint name="Untitled.078" type="fixed">
      <origin xyz="-0.15 0.025 0.06" rpy="1.5708 0 0"/>
      <parent link="Untitled.004"/>
      <child link="Untitled.078"/>
    </joint>

    <joint name="Untitled.079" type="fixed">
      <origin xyz="-0.00145 1.25375 0.0347" rpy="3.14159 0 1.5708"/>
      <parent link="Untitled.013"/>
      <child link="Untitled.079"/>
    </joint>

    <joint name="Untitled.080" type="fixed">
      <origin xyz="0.025 0 0.03113" rpy="0 0 0"/>
      <parent link="Untitled.029"/>
      <child link="Untitled.080"/>
    </joint>

    <joint name="Untitled.081" type="fixed">
      <origin xyz="0.02762 -0.0014 0.03161" rpy="0 0 0"/>
      <parent link="Untitled.032"/>
      <child link="Untitled.081"/>
    </joint>

    <joint name="Untitled.082" type="fixed">
      <origin xyz="0 -0.035 0.11744" rpy="0 0 0"/>
      <parent link="Untitled.027"/>
      <child link="Untitled.082"/>
    </joint>

    <joint name="Untitled.083" type="fixed">
      <origin xyz="0 -0.035 0.12198" rpy="0 0 0"/>
      <parent link="Untitled.030"/>
      <child link="Untitled.083"/>
    </joint>

    <joint name="Untitled.084" type="fixed">
      <origin xyz="0 -0.035 0.11828" rpy="0 0 0"/>
      <parent link="Untitled.033"/>
      <child link="Untitled.084"/>
    </joint>

    <joint name="Untitled.085" type="fixed">
      <origin xyz="0.05 0 -0.04" rpy="0 0 3.14159"/>
      <parent link="Untitled.003"/>
      <child link="Untitled.085"/>
    </joint>

    <joint name="Untitled.086" type="fixed">
      <origin xyz="0.03 0 -0.04" rpy="0 0 0"/>
      <parent link="Untitled.002"/>
      <child link="Untitled.086"/>
    </joint>

    <joint name="Untitled.087" type="fixed">
      <origin xyz="-0.05 0 -0.04" rpy="0 0 0"/>
      <parent link="Untitled"/>
      <child link="Untitled.087"/>
    </joint>

    <joint name="Untitled.088" type="fixed">
      <origin xyz="-0.03 0 -0.04" rpy="0 0 3.14159"/>
      <parent link="Untitled.001"/>
      <child link="Untitled.088"/>
    </joint>

    <joint name="Untitled.089" type="fixed">
      <origin xyz="0.04 0.0124 -0.035" rpy="0 0 3.14159"/>
      <parent link="Untitled.016"/>
      <child link="Untitled.089"/>
    </joint>

    <joint name="Untitled.090" type="fixed">
      <origin xyz="0.02 -0.0124 -0.045" rpy="0 0 0"/>
      <parent link="Untitled.014"/>
      <child link="Untitled.090"/>
    </joint>

    <joint name="Untitled.091" type="fixed">
      <origin xyz="-0.05 -0.0124 -0.045" rpy="0 0 0"/>
      <parent link="Untitled.012"/>
      <child link="Untitled.091"/>
    </joint>

    <joint name="Untitled.092" type="fixed">
      <origin xyz="-0.03 0.0124 -0.035" rpy="0 0 3.14159"/>
      <parent link="Untitled.010"/>
      <child link="Untitled.092"/>
    </joint>

    <joint name="Untitled.093" type="fixed">
      <origin xyz="0.01 -0.01 0.00115" rpy="0 0 0"/>
      <parent link="Untitled.036"/>
      <child link="Untitled.093"/>
    </joint>

    <joint name="Untitled.094" type="fixed">
      <origin xyz="-0.03 -0.04997 -0.03088" rpy="0 1.5708 0"/>
      <parent link="Untitled.036"/>
      <child link="Untitled.094"/>
    </joint>

    <joint name="Untitled.095" type="fixed">
      <origin xyz="-0.02003 -0.0025 0.03571" rpy="0 0 0"/>
      <parent link="Untitled.094"/>
      <child link="Untitled.095"/>
    </joint>

    <joint name="Untitled.096" type="fixed">
      <origin xyz="0 0.05168 0.0085" rpy="0 1.5708 0"/>
      <parent link="Untitled.038"/>
      <child link="Untitled.096"/>
    </joint>

    <joint name="Untitled.097" type="continuous">
      <origin xyz="-0.00259 0.125 0.0024" rpy="1.5708 0 -3.14159"/>
      <parent link="Untitled.004"/>
      <child link="Untitled.097"/>
      <axis xyz="0 0 1.0"/>
      <limit effort="0.01" velocity="0.1"/>
    </joint>

    <joint name="Untitled.098" type="continuous">
      <origin xyz="-0.00259 -0.135 0.0024" rpy="1.5708 0 0"/>
      <parent link="Untitled.004"/>
      <child link="Untitled.098"/>
      <axis xyz="0 0 1.0"/>
      <limit effort="0.01" velocity="0.1"/>
    </joint>

    <joint name="Untitled.099" type="continuous">
      <origin xyz="-0.0026 0.13 0" rpy="1.5708 0 -3.14159"/>
      <parent link="Untitled.009"/>
      <child link="Untitled.099"/>
      <axis xyz="0 0 1.0"/>
      <limit effort="0.01" velocity="0.1"/>
    </joint>

    <joint name="Untitled.100" type="continuous">
      <origin xyz="-0.0026 -0.13 0" rpy="1.5708 0 0"/>
      <parent link="Untitled.009"/>
      <child link="Untitled.100"/>
      <axis xyz="0 0 1.0"/>
      <limit effort="0.01" velocity="0.1"/>
    </joint>

    <joint name="Untitled.101" type="fixed">
      <origin xyz="-0.02 0.03 -0.05" rpy="1.5708 0 0"/>
      <parent link="Untitled.004"/>
      <child link="Untitled.101"/>
    </joint>

    <joint name="Untitled.102" type="fixed">
      <origin xyz="-0.01 0.05 0.03" rpy="0 0 0"/>
      <parent link="Untitled.101"/>
      <child link="Untitled.102"/>
    </joint>

    <joint name="Untitled.104" type="fixed">
      <origin xyz="-0.02 0.035 -0.0524" rpy="1.5708 0 0"/>
      <parent link="Untitled.009"/>
      <child link="Untitled.104"/>
    </joint>

    <joint name="Untitled.105" type="fixed">
      <origin xyz="-0.01 0.05 0.03" rpy="0 0 0"/>
      <parent link="Untitled.104"/>
      <child link="Untitled.105"/>
    </joint>

    <joint name="Untitled.106" type="fixed">
      <origin xyz="0.115 -0.025 0.06" rpy="1.5708 0 -3.14159"/>
      <parent link="Untitled.004"/>
      <child link="Untitled.106"/>
    </joint>

    <joint name="Untitled.107" type="fixed">
      <origin xyz="0.165 -0.025 0.06" rpy="1.5708 0 -1.5708"/>
      <parent link="Untitled.004"/>
      <child link="Untitled.107"/>
    </joint>

    <joint name="Untitled.108" type="fixed">
      <origin xyz="0.17 0.025 0.06" rpy="1.5708 0 0"/>
      <parent link="Untitled.004"/>
      <child link="Untitled.108"/>
    </joint>

    <joint name="Untitled.109" type="fixed">
      <origin xyz="0.11633 0.02712 0.06201" rpy="1.5708 0 1.5708"/>
      <parent link="Untitled.004"/>
      <child link="Untitled.109"/>
    </joint>

    <joint name="Untitled.110" type="fixed">
      <origin xyz="-1.25101 0.00279 -0.00759" rpy="0 0 -1.5708"/>
      <parent link="Untitled.052"/>
      <child link="Untitled.110"/>
    </joint>

    <joint name="Untitled.111" type="fixed">
      <origin xyz="1.24899 0.00279 -0.00759" rpy="0 0 -1.5708"/>
      <parent link="Untitled.052"/>
      <child link="Untitled.111"/>
    </joint>

    <joint name="Untitled.112" type="fixed">
      <origin xyz="0.01319 0 0.13722" rpy="0 0 0"/>
      <parent link="Untitled.022"/>
      <child link="Untitled.112"/>
    </joint>

    <joint name="Untitled.113" type="fixed">
      <origin xyz="-0.00319 0 0.06094" rpy="0 0 0"/>
      <parent link="Untitled.112"/>
      <child link="Untitled.113"/>
    </joint>

    <joint name="Untitled.114" type="fixed">
      <origin xyz="0.05 0 0.02" rpy="1.5708 0 0"/>
      <parent link="Untitled.113"/>
      <child link="Untitled.114"/>
    </joint>

    <joint name="Untitled.115" type="fixed">
      <origin xyz="0 -0.05553 0.00324" rpy="0 0 0"/>
      <parent link="Untitled.035"/>
      <child link="Untitled.115"/>
    </joint>

    <joint name="Untitled.116" type="fixed">
      <origin xyz="0 -0.039 0.10655" rpy="0 0 0"/>
      <parent link="Untitled.115"/>
      <child link="Untitled.116"/>
    </joint>

    <joint name="Untitled.117" type="fixed">
      <origin xyz="0 -0.025 -0.07" rpy="0 0 0"/>
      <parent link="Untitled.116"/>
      <child link="Untitled.117"/>
    </joint>

    <joint name="Untitled.118" type="fixed">
      <origin xyz="0 -0.02859 0.00917" rpy="-1.5708 0 0"/>
      <parent link="Untitled.037"/>
      <child link="Untitled.118"/>
    </joint>

    <joint name="Untitled.119" type="fixed">
      <origin xyz="-0.00067 -0.08027 0" rpy="-1.5708 -1.5708 0"/>
      <parent link="Untitled.096"/>
      <child link="Untitled.119"/>
    </joint>

    <material name="Material.001">
      <color rgba="0 0 0 1.0"/>
    </material>

    <material name="Material.002">
      <color rgba="0 0 0 1.0"/>
    </material>

    <material name="Material.003">
      <color rgba="0 0 0 1.0"/>
    </material>

    <material name="Material.004">
      <color rgba="0 0 0 1.0"/>
    </material>

    <material name="Material.005">
      <color rgba="0.64 0.64 0.64 1.0"/>
    </material>

    <material name="Material.006">
      <color rgba="0.08 0.08 0.08 1.0"/>
    </material>

    <material name="Material.007">
      <color rgba="0.64 0.64 0.64 1.0"/>
    </material>

    <material name="Material.008">
      <color rgba="0 0 0 1.0"/>
    </material>

    <material name="Material.009">
      <color rgba="0 0 0 1.0"/>
    </material>

    <material name="Material.010">
      <color rgba="0 0 0 1.0"/>
    </material>

    <material name="Material.011">
      <color rgba="0.64 0.64 0.64 1.0"/>
    </material>

    <material name="Material.012">
      <color rgba="0.16 0.16 0.16 1.0"/>
    </material>

    <material name="Material.013">
      <color rgba="0.16 0.16 0.16 1.0"/>
    </material>

    <material name="Material.014">
      <color rgba="0.64 0.64 0.64 1.0"/>
    </material>

    <material name="Material.015">
      <color rgba="0.16 0.16 0.16 1.0"/>
    </material>

    <material name="Material.016">
      <color rgba="0.16 0.16 0.16 1.0"/>
    </material>

    <material name="Material.017">
      <color rgba="0.64 0.64 0.64 1.0"/>
    </material>

    <material name="Material.018">
      <color rgba="0.16 0.16 0.16 1.0"/>
    </material>

    <material name="Material.019">
      <color rgba="0.16 0.16 0.16 1.0"/>
    </material>

    <material name="Material.020">
      <color rgba="0.64 0.64 0.64 1.0"/>
    </material>

    <material name="Material.021">
      <color rgba="0.64 0.64 0.64 1.0"/>
    </material>

    <material name="Material.022">
      <color rgba="0.64 0.64 0.64 1.0"/>
    </material>

    <material name="Material.023">
      <color rgba="0.64 0.64 0.64 1.0"/>
    </material>

    <material name="Material.024">
      <color rgba="0.16 0.16 0.16 1.0"/>
    </material>

    <material name="Material.025">
      <color rgba="0.64 0.64 0.64 1.0"/>
    </material>

    <material name="Material.026">
      <color rgba="0.09 0.09 0.09 1.0"/>
    </material>

    <material name="Material.027">
      <color rgba="0.76 0.76 0.76 1.0"/>
    </material>

    <material name="Material.028">
      <color rgba="0 0 0 1.0"/>
    </material>

    <material name="Material.029">
      <color rgba="1.0 1.0 1.0 1.0"/>
    </material>

    <material name="Material.030">
      <color rgba="0.64 0.64 0.64 1.0"/>
    </material>

    <material name="Material.031">
      <color rgba="0 0 0 1.0"/>
    </material>

    <material name="Material.032">
      <color rgba="0 0 0 1.0"/>
    </material>

    <material name="Material.033">
      <color rgba="0.16 0.16 0.16 1.0"/>
    </material>

    <material name="Material.034">
      <color rgba="0.48 0.48 0.48 1.0"/>
    </material>

    <material name="Material.035">
      <color rgba="0.64 0.64 0.64 1.0"/>
    </material>

    <material name="Material.036">
      <color rgba="0.4 0.4 0.4 1.0"/>
    </material>

    <material name="Material.037">
      <color rgba="0 0 0 1.0"/>
    </material>

    <material name="Material.038">
      <color rgba="0.72 0.72 0.72 1.0"/>
    </material>

    <material name="Material.039">
      <color rgba="0.64 0.64 0.64 1.0"/>
    </material>

    <material name="Material.040">
      <color rgba="0.56 0.56 0.56 1.0"/>
    </material>

    <material name="Material.041">
      <color rgba="0.64 0.64 0.64 1.0"/>
    </material>

    <material name="Material.042">
      <color rgba="0.64 0.64 0.64 1.0"/>
    </material>

    <material name="Material.043">
      <color rgba="0.16 0.16 0.16 1.0"/>
    </material>

    <material name="Material.044">
      <color rgba="1.0 1.0 1.0 1.0"/>
    </material>

    <material name="Material.045">
      <color rgba="0 0 0 1.0"/>
    </material>

    <material name="Material.048">
      <color rgba="0.64 0.64 0.64 1.0"/>
    </material>

    <material name="Material.049">
      <color rgba="0.64 0.64 0.64 1.0"/>
    </material>

    <material name="Material.050">
      <color rgba="0.16 0.16 0.16 1.0"/>
    </material>

    <material name="Material.051">
      <color rgba="0.16 0.16 0.16 1.0"/>
    </material>

    <material name="Material.052">
      <color rgba="0.64 0.64 0.64 1.0"/>
    </material>

    <material name="Material.053">
      <color rgba="0.16 0.16 0.16 1.0"/>
    </material>

    <material name="Material.054">
      <color rgba="0.16 0.16 0.16 1.0"/>
    </material>

  </robot>
